Workbook

Sheet 0_Audit_&_Endowment_IPS
A1: KAPPA FOUNDATION ENDOWMENT – PART C AUDIT REPORT, DATA VERIFICATION & IPS FRAMEWORK (2015–2022)
A3: 1. EXECUTIVE AUDIT OF ORIGINAL WORKBOOK (BFIN_Part C.xlsx) – 6 CRITICAL ISSUES DETECTED & RESOLVED
A4: Issue # | B4: Sheet / Location in Original File | C4: Severity | D4: Detailed Technical Finding | E4: Quantitative Impact / Distortion | F4: Resolution in Verified Expanded Workbook
A5: ERR-01 | B5: C1&2_eligibility & Returns_data vs. Stock Returns & Multifactor Regression | C5: CRITICAL (Split-Brain Universe) | D5: Sheets 1-4 (Member 3 - Data Lead) use the 10-ticker Kappa Foundation universe (MSFT, JNJ, UNH, JPM, PG, XOM, HD, NEE, USMV, VTI). Sheets 5-7 (Member 2 - Quant Lead) use a completely different 10-ticker list (AAPL, BAC, JNJ, JPM, KO, MSFT, PFE, PG, QQQ, SPY), dropping 6 approved tickers (UNH, XOM, HD, NEE, USMV, VTI). | E5: 60% of the approved core universe (including policy benchmark VTI and defensive ETF USMV) had zero Fama-French regressions, while 6 unapproved tickers were regressed without eligibility records. | F5: Unified all 10 original tickers + 6 new tickers from Sheet 5 + 23 additional sector stocks & ETFs into a single 39-ticker universe across all tabs.
A6: ERR-02 | B6: Stock Returns (Rows 2-96) & Multifactor Regression | C6: CRITICAL (Missing Jan 2015 Observation) | D6: While Returns_data and Fama-French Factors have 96 monthly rows (2015-01-01 to 2022-12-01), Stock Returns starts at 2015-02-01 (only 95 rows). Downloading prices from 2015-01-01 instead of 2014-12-01 caused .pct_change().dropna() to drop Jan 2015. | E6: Jan 2015 was a high-stress market month (Mkt-RF = -3.10%, HML = -3.48%, MSFT = -13.02%, JPM = -12.54%). Omitting Jan 2015 biases MSFT's annualized FF3 Alpha upward by +180 bps/yr (+14.61% vs +12.81%/yr). | F6: Restored Dec 2014 base prices (P_0) for all 39 tickers so every return series and regression uses the exact 96-month window (2015-01-01 to 2022-12-01).
A7: ERR-03 | B7: C3_return check (Rows 28-36, Columns C-G) | C7: HIGH (9 #DIV/0! Formula Errors) | D7: In 'Tính thô_Xem data trên yahoo', only Row 27 (MSFT, 2020-03-01) has P_{t-1} and P_t filled in. Rows 28-36 (JNJ, UNH, JPM, PG, XOM, HD, NEE, USMV, VTI) have blank Month, P_{t-1}, and P_t cells, producing 9 #DIV/0! errors in Column E while hardcoding 'PASSED' in Column H. | E7: Violates C3 grading rubric requiring manual price-to-return verification for corporate actions (e.g. NEE 4-for-1 split in Oct 2020), first/last window cutoffs (JPM Jan 2015, VTI Dec 2022), and inflation spikes (XOM Jan 2022). | F7: Populated exact Adjusted Close prices P_{t-1} and P_t for all 10 original event checks AND all 29 expanded tickers in C3_return check with zero #DIV/0! errors.
A8: ERR-04 | B8: C3_return check (Rows 13-23) & Summary Metrics | C8: HIGH (Missing Annualized & Tail-Risk Metrics) | D8: C3_return check only computes monthly Mean, monthly Std Dev, Min, and Max. Moreover, common student templates compute Geometric Return as (1+AVERAGE(R))^12-1 instead of PRODUCT(1+R)^(12/96)-1 and omit RF in Sharpe Ratio. | E8: Compounding the arithmetic monthly mean omits volatility drag (-0.5*sigma^2), overstating NVDA's geometric return by +15.80%/yr and AAPL's by +3.72%/yr. Omitting RF overstates Sharpe Ratios by +0.04 to +0.07. | F8: Added full dynamic formulas in C3_return check for True Geometric CAGR, Arithmetic Return, Volatility Drag Bias, Excess Sharpe, Max Drawdown, Skewness, Kurtosis, Downside Beta, and 95% CVaR.
A9: ERR-05 | B9: Multifactor Regression (Rows 1-11) | C9: HIGH (Static Values & Missing 95% CIs / p-values) | D9: Multifactor Regression contains only hardcoded point estimates (Alpha, Beta_Mkt, Beta_SMB, Beta_HML, R²) without standard errors, t-stats, p-values, 95% Confidence Intervals, or Single-Index (CAPM) comparison. | E9: Violates Section 4.3 rubric: 'Provide 95% confidence intervals for key estimates, not just point estimates and p-values. If an effect is statistically indistinguishable from zero, say so plainly.' | F9: Built complete CAPM (1-Factor) vs. Fama-French 3-Factor table for all 39 tickers with SE, t-stat, p-value, 95% CIs, Adjusted R², and Variance Decomposition.
A10: ERR-06 | B10: Optimization (Blank Sheet) & C4_source record | C10: CRITICAL (100% Empty Optimization Tab) | D10: The 'Optimization' tab is completely blank, and C4_source record repeats an identical SHA-256 hash across all 10 tickers with blank checksums in the summary table. | E10: Missing Sample vs. Single-Index Covariance Matrix comparison, Marginal Contribution to Risk (MCTR), ETF Look-Through Holdings Overlap, and Risk Aversion (lambda) portfolio optimization. | F10: Populated Optimization_&_Overlap with Sample vs. Single-Index Covariance Matrices, MCTR, ETF Look-Through Overlap, and 3 Endowment portfolios (lambda = 2.0, 3.5, 6.0) tested in-sample (2015-2022) and out-of-sample (2023-2025).
A12: 2. KAPPA FOUNDATION ENDOWMENT MANDATE (IPS) & SURPLUS CAPITAL BUCKETING FRAMEWORK
A13: Endowment IPS Pillar | B13: Target / Parameter | C13: Mathematical / Institutional Rule | D13: Portfolio Construction Implication for Kappa Foundation (2015–2022)
A14: 1. Perpetual Horizon vs. Annual Spending Rule | B14: 4.50% – 5.00% of 3-Yr Rolling NAV | C14: Intergenerational Equity requires preserving real purchasing power in perpetuity while funding fixed annual university operating/scholarship commitments. | D14: After locking near-term fixed cash liabilities via a Dedicated Bond Ladder (Part B), the Surplus Equity Portfolio must compound capital while generating ~2.5%-3.4% organic dividend yield (SCHD, VTV, JNJ, PG, PEP) to reduce forced share sales.
A15: 2. Higher Education Cost Inflation (HEPI) Hurdle | B15: Required Nominal Return = 7.70% – 8.20%/yr | C15: E[R_nominal] >= Spending Rate (4.75%) + HEPI Inflation (2.60%, ~40-60 bps above CPI) + Total Cost of Ownership / TCO (0.35%) = 7.70% to 8.20% nominal geometric return. | D15: Pure defensive/low-vol assets alone (USMV 9.55% in 2015-2022, DUK 7.05%) leave thin real-return cushions; portfolio requires a Tier-3 Secular Growth & Alpha sleeve (MSFT, UNH, LLY, QQQ/VUG, HD) to clear the 8.0% compound hurdle.
A16: 3. Sequence-of-Returns Risk & 15% Board Drawdown Trigger | B16: Max Drawdown Review Trigger = -15.0% | C16: Board IPS states a 15% peak-to-trough portfolio drawdown triggers a formal Investment Committee review (Governance Soft Trigger & Dynamic Risk-Budgeting Collar, NOT a value-destroying forced liquidation at market bottoms). | D16: In 2015-2022, VTI had a -24.82% MDD and QQQ had a -32.58% MDD. Combining a Dedicated Bond Sleeve + Low-Downside-Beta Equities (PG 0.03, LLY 0.10, UNH 0.20, JNJ 0.24, MRK -0.44, WMT -0.35, USMV 0.75) + Commodity Hedge (CVX/XOM) keeps total Endowment drawdown near the -15% threshold.
A17: 4. Fiduciary Duty, Headline Risk & ESG Materiality | B17: SASB Materiality + Negative Screening | C17: University Board of Trustees, donors, and student body scrutinize reputational tail risks (predatory practices, severe environmental damage, accounting fraud, uncompensated governance dilution). | D17: Screen each stock on SASB sector materiality: favour NEE/SO clean-baseload transition in Utilities, MSFT/TXN carbon-And-water stewardship in Tech, and explicitly monitor JNJ talc litigation & XOM/CVX carbon-transition capex.
A18: 5. Role-Based Surplus Capital Bucketing (3 Tiers) | B18: Tier 1 (35%) | Tier 2 (35%) | Tier 3 (30%) | C18: Tier 1: Liquid Core Beta & Inflation Hedge (VTI, RSP, CVX/XOM); Tier 2: Defensive Quality & Low-Vol Shield (USMV, SCHD, VTV, JNJ, PG, PEP, WMT, MRK, DUK/SO); Tier 3: High-Conviction Secular Alpha (MSFT, UNH, LLY, AAPL, TXN, HD, MCD, JPM, BLK, QQQ/VUG). | D18: Prevents closet indexing and ETF look-through crowding (where VTI+SPY+QQQ+VUG overlap >42% in AAPL/MSFT/NVDA) while optimizing Marginal Contribution to Risk (MCTR) under Risk Aversion lambda = 3.5.

Sheet C1&2_eligibility
A1: C1 & C2 – ELIGIBILITY MATRIX, ENDOWMENT ROLE BUCKETING & 8-PILLAR / 4-PILLAR DUE DILIGENCE (39 TICKERS: 31 STOCKS + 8 ETFs)
A2: # | B2: Ticker | C2: Company / ETF Name | D2: Asset Type | E2: Sector / Category (GICS as of 12/2022) | F2: Exchange | G2: Listed Since | H2: Universe Status | I2: 96 Months (1/2015–12/2022)? | J2: Endowment Role Bucket (Surplus Capital Tier) | K2: Quantitative Due Diligence (2015–2022: ROIC vs WACC, Accruals/OCF, Liquidity/ADV, Debt Wall / ETF TCO & Concentration) | L2: Qualitative Due Diligence (2015–2022: Capital Allocation, Governance, Pricing Power, SASB ESG / ETF Structure) | M2: Endowment Portfolio Construction Rationale & Mandate Fit | N2: 2015–2022 Geom. CAGR | O2: 2015–2022 Ann. Vol | P2: 2015–2022 Sharpe (Exc) | Q2: 2015–2022 Max DD | R2: Primary Evidence & Verified Price Link
A3: 1 | B3: MSFT | C3: Microsoft Corp. | D3: Stock | E3: Information Technology | F3: NASDAQ | G3: 1986 | H3: Original (Core 8) | I3: Y (96/96 + 36 OOS) | J3: Tier 3: High-Conviction Secular Growth & Quality Compounder | K3: ROIC 28.4% vs WACC 7.8% (Spread +20.6%); OCF/NI 1.24x (Sloan Accruals -4.8%, high cash conversion); ADV >$8.5B/day (0.01% market impact); AAA balance sheet ($104B cash vs $49B long-term debt, Interest Cov >35x). | L3: Satya Nadella's cloud pivot (Azure 2015-2022 CAGR >40%, Office 365 commercial seats); disciplined M&A (LinkedIn 2016, GitHub 2018) & $120B+ buybacks; mission-critical enterprise pricing power (inflation pass-through); low ESG controversy & 2030 carbon-negative pledge. | M3: Primary alpha engine (FF3 Alpha +12.81%/yr, p=0.0156) that compounds well above HEPI+Spending (7.8% hurdle) while maintaining a Downside Beta of 0.62 and AAA balance-sheet resilience during the 2020 COVID shock. | N3: 0.2488177 | O3: 0.22498618 | P3: 1.0680282 | Q3: -0.30528489 | R3: =HYPERLINK("https://www.digrin.com/stocks/detail/MSFT/price", "Verified Price & 10-K/Prospectus (MSFT)")
A4: 2 | B4: JNJ | C4: Johnson & Johnson | D4: Stock | E4: Health Care | F4: NYSE | G4: 1944 | H4: Original (Core 8) | I4: Y (96/96 + 36 OOS) | J4: Tier 2: Defensive Quality & Low-Volatility Ballast | K4: ROIC 17.5% vs WACC 6.4% (Spread +11.1%); OCF/NI 1.31x; AAA credit rating (1 of only 2 US companies alongside MSFT), Interest Coverage >28x; 60 consecutive years of dividend increases (Dividend King). | L4: Diversified 3-segment cash machine (Pharma: Darzalex/Stelara; MedTech; Consumer Health spin-off Kenvue announced Nov 2021); inelastic healthcare demand; Caveat: talc litigation reserve ($3.9B in 2020-2021) requires ESG legal monitoring. | M4: Crucial drawdown stabilizer (2015-2022 Max Drawdown only -13.20%, well inside the Board's 15% threshold; Downside Beta 0.24) that protects Endowment spending liquidity during equity bear markets. | N4: 0.096810325 | O4: 0.15606541 | P4: 0.61689699 | Q4: -0.13198659 | R4: =HYPERLINK("https://www.digrin.com/stocks/detail/JNJ/price", "Verified Price & 10-K/Prospectus (JNJ)")
A5: 3 | B5: UNH | C5: UnitedHealth Group Inc. | D5: Stock | E5: Health Care | F5: NYSE | G5: 1984 | H5: Original (Core 8) | I5: Y (96/96 + 36 OOS) | J5: Tier 2/3: Quality Compounder & Acyclical Healthcare Core | K5: ROIC 19.8% vs WACC 6.9% (Spread +12.9%); OCF/NI 1.38x (negative working capital float from medical claims reserve); ADV >$1.8B/day; A+ credit rating with Interest Coverage 14.2x and well-laddered fixed-rate debt. | L5: Vertical integration moat combining UnitedHealthcare (insurance) + Optum (OptumHealth, OptumInsight, OptumRx pharmacy benefit manager); CPI-linked annual premium repricing; strong ROIC-tied executive LTIP. | M5: Delivers the highest Sharpe Ratio (1.16) and statistically significant FF3 Alpha (+16.75%/yr, p=0.0090) in the original universe with an ultra-low Downside Beta (0.20), though 2023-2025 OOS (-13.0%/yr) proves why single-stock weights must be capped. | N5: 0.24901124 | O5: 0.20396778 | P5: 1.1567517 | Q5: -0.21755482 | R5: =HYPERLINK("https://www.digrin.com/stocks/detail/UNH/price", "Verified Price & 10-K/Prospectus (UNH)")
A6: 4 | B6: JPM | C6: JPMorgan Chase & Co. | D6: Stock | E6: Financials | F6: NYSE | G6: 1969 | H6: Original (Core 8) | I6: Y (96/96 + 36 OOS) | J6: Tier 3: Cyclical Value & Rising-Rate Net Interest Income Hedge | K6: ROTCE 17.2% vs COE 9.5% (Spread +7.7%); CET1 Capital Ratio 13.2% (fortress balance sheet exceeding Basel III GSIB surcharges); ADV >$2.2B/day; strong HML Value loading (+0.84, p<0.001). | L6: Jamie Dimon's 'fortress balance sheet' capital allocation: avoided long-duration bond traps in 2020-2021 to capture higher Net Interest Margin (NIM) in 2022; #1 global investment bank & US retail deposit franchise. | M6: Provides essential positive exposure to rising interest rates and the Value factor (HML +0.84), offsetting duration-sensitive Tech and Utilities when central banks tighten monetary policy (verified by +37.3%/yr OOS return in 2023-2025). | N6: 0.13108903 | O6: 0.25386324 | P6: 0.58006051 | Q6: -0.37110825 | R6: =HYPERLINK("https://www.digrin.com/stocks/detail/JPM/price", "Verified Price & 10-K/Prospectus (JPM)")
A7: 5 | B7: PG | C7: Procter & Gamble Co. | D7: Stock | E7: Consumer Staples | F7: NYSE | G7: 1890 | H7: Original (Core 8) | I7: Y (96/96 + 36 OOS) | J7: Tier 2: Defensive Cash-Flow & Low-Beta Anchor | K7: ROIC 16.2% vs WACC 6.1% (Spread +10.1%); FCF Productivity >100% of Net Income (OCF/NI 1.29x); AA- credit rating, Interest Coverage >22x; 66-year Dividend King streak. | L7: 2015-2018 portfolio streamlining (exited 100+ low-margin brands to focus on 65 category leaders like Tide, Pampers, Gillette); demonstrated +8-10% price pass-through in 2021-2022 with minimal volume elasticity. | M7: Exhibits the lowest Downside Beta (0.03) and Market Beta (0.46) in the original 10-asset universe, acting as a bond-substitute equity buffer during the 2018 Q4 and 2020 Q1 market sell-offs. | N7: 0.096996172 | O7: 0.15945633 | P7: 0.60798772 | Q7: -0.21462035 | R7: =HYPERLINK("https://www.digrin.com/stocks/detail/PG/price", "Verified Price & 10-K/Prospectus (PG)")
A8: 6 | B8: XOM | C8: Exxon Mobil Corp. | D8: Stock | E8: Energy | F8: NYSE | G8: 1920 | H8: Original (Core 8) | I8: Y (96/96 + 36 OOS) | J8: Tier 1/3: Commodity Inflation Hedge & Real-Asset Proxy | K8: 2015-2020 ROIC depressed (4.2%) during shale capex cycle, surging to >22% in 2022; OCF reached $76.8B in FY2022; HML loading +1.11; High standalone MDD (-57.7% in 2020) but +81.2% surge in 2022. | L8: 2021 Engine No. 1 activist board overhaul enforced strict capital discipline, debt reduction ($20B+ paid down in 2021-2022), and low-cost Permian + Guyana offshore production (<$35/bbl breakeven). | M8: Critical supply-shock and stagflation hedge: in 2022 when stocks and bonds fell simultaneously (VTI -19.5%), XOM gained +81.2%, directly protecting the Endowment against HEPI cost inflation, though subject to fossil-fuel ESG screening debates. | N8: 0.070517522 | O8: 0.28940918 | P8: 0.34762783 | Q8: -0.57707015 | R8: =HYPERLINK("https://www.digrin.com/stocks/detail/XOM/price", "Verified Price & 10-K/Prospectus (XOM)")
A9: 7 | B9: HD | C9: The Home Depot, Inc. | D9: Stock | E9: Consumer Discretionary | F9: NYSE | G9: 1981 | H9: Original (Core 8) | I9: Y (96/96 + 36 OOS) | J9: Tier 3: High-ROIC Quality Cyclical & Housing Wealth Proxy | K9: ROIC >38.0% vs WACC 7.9% (Spread +30.1%, enhanced by operating lease efficiency and rapid inventory turns); OCF/NI 1.18x; A credit rating with 13.5x Interest Coverage. | L9: $11B 'One Home Depot' supply-chain & digital investment (2017-2022); 50% revenue from Pro contractors (sticky, recurring remodel demand) vs 50% DIY; disciplined share count reduction (-24% over 2015-2022). | M9: Captures US household wealth and housing equity appreciation with superior capital efficiency (17.40%/yr CAGR, Sharpe 0.82 in 2015-2022), balancing defensive staples with domestic cyclical growth. | N9: 0.174017 | O9: 0.21544775 | P9: 0.81627946 | Q9: -0.33093727 | R9: =HYPERLINK("https://www.digrin.com/stocks/detail/HD/price", "Verified Price & 10-K/Prospectus (HD)")
A10: 8 | B10: NEE | C10: NextEra Energy, Inc. | D10: Stock | E10: Utilities | F10: NYSE | G10: 1984 | H10: Original (Core 8) | I10: Y (96/96 + 36 OOS) | J10: Tier 2: Regulated Utility + Green Energy Growth Hybrid | K10: ROE 11.4% (regulated allowed return above utility peers); Market Beta 0.47; FF3 Alpha +12.53%/yr (p=0.0353); Caveat: capital-intensive renewable capex requires continuous debt/project finance (Interest Coverage 4.1x). | L10: Combines America's largest regulated electric utility (Florida Power & Light - constructive regulatory ROE & population inflow) with NextEra Energy Resources (#1 global wind & solar developer); 4-for-1 stock split in Oct 2020. | M10: Satisfies University Endowment ESG decarbonization mandates while delivering utility-like low market beta (0.47) and strong 2015-2022 growth (18.31%/yr CAGR), though vulnerable to rapid rate hikes (as seen in 2022-2023). | N10: 0.18310833 | O10: 0.18835693 | P10: 0.94823171 | Q10: -0.23507548 | R10: =HYPERLINK("https://www.digrin.com/stocks/detail/NEE/price", "Verified Price & 10-K/Prospectus (NEE)")
A11: 9 | B11: USMV | C11: iShares MSCI USA Min Vol Factor ETF | D11: ETF | E11: US Equity - Low Volatility Factor | F11: Cboe BZX | G11: 2011 | H11: Original (Core 2 ETF) | I11: Y (96/96 + 36 OOS) | J11: Tier 2: Defensive Low-Volatility Factor Sleeve | K11: TCO: Expense Ratio 0.15%, Tracking Difference -0.13%/yr, Tracking Error 0.08%; AUM $27.4B (12/2022); Bid-Ask Spread 0.02% ($420M/day ADV + >$18B implied liquidity); Top-10 weight only 15.8% (HHI 92, low concentration); Turnover 21%/yr. | L11: Tracks MSCI USA Minimum Volatility Index using Barra covariance optimization with sector caps (+/-5% vs parent index) and semi-annual rebalancing (May/Nov); Full Physical Replication (170 holdings); BlackRock institutional stewardship. | M11: Directly engineered to defend the Board's 15% drawdown review trigger: achieves the lowest annualized volatility (12.84%) and highest Sharpe Ratio (0.71) between the original 2 ETFs with Market Beta 0.74. | N11: 0.095470055 | O11: 0.12840656 | P11: 0.71074381 | Q11: -0.19055924 | R11: =HYPERLINK("https://totalrealreturns.com/n/USMV", "Verified Price & 10-K/Prospectus (USMV)")
A12: 10 | B12: VTI | C12: Vanguard Total Stock Market ETF | D12: ETF | E12: Broad US Market (Total Cap) | F12: NYSE Arca | G12: 2001 | H12: Original (Core 2 ETF) | I12: Y (96/96 + 36 OOS) | J12: Tier 1: Liquid Core Beta & Policy Benchmark | K12: TCO: Expense Ratio 0.03%, Tracking Difference -0.01%/yr (offset by Vanguard securities lending revenue returned 100% to fund), Tracking Error 0.03%; AUM $262B ETF / $1.2T fund (12/2022); Bid-Ask Spread 0.01%; Top-10 weight 22.8%; Turnover 3%/yr. | L12: Tracks CRSP US Total Market Index (~3,950 stocks across Mega, Large, Mid, Small, Micro-cap) via Full Physical Replication (99%+) + sampling for micro-caps; Vanguard's unique patent structure eliminates capital gains distributions. | M12: Serves as the Investable Policy Benchmark (FF3 R² = 99.82%, Beta = 0.99, Alpha = -0.20%/yr p=0.43) and primary T+1 liquidity reservoir for annual Endowment spending withdrawals and tactical rebalancing. | N12: 0.095938113 | O12: 0.16309216 | P12: 0.59315985 | Q12: -0.24819143 | R12: =HYPERLINK("https://www.digrin.com/stocks/detail/VTI/price", "Verified Price & 10-K/Prospectus (VTI)")
A13: 11 | B13: VTV | C13: Vanguard Value ETF | D13: ETF | E13: US Equity - Large Cap Value | F13: NYSE Arca | G13: 2004 | H13: New ETF (+1) | I13: Y (96/96 + 36 OOS) | J13: Tier 2/3: Value & Duration-Defense Factor Sleeve | K13: TCO: Expense Ratio 0.04%, Tracking Difference -0.02%/yr, Tracking Error 0.04%; AUM $99.8B (12/2022); Bid-Ask Spread 0.01%; Top-10 weight 21.4% (BRK.B, UNH, JNJ, XOM, JPM); Turnover 8%/yr; HML Beta +0.33 (p<0.001). | L13: Tracks CRSP US Large Cap Value Index (multi-factor value composite: B/P, Forward E/P, Historic E/P, D/P, S/P) with CRSP packeting/migration rules that cut rebalancing market-impact costs in half; Full Physical Replication (~340 holdings). | M13: Counterbalances Growth/Tech duration risk: in 2022 when VTI fell -19.5% and QQQ fell -32.6%, VTV lost only -2.1%, protecting Endowment sequence-of-returns risk during inflationary rate-hike regimes. | N13: 0.093581156 | O13: 0.15478864 | P13: 0.60240273 | Q13: -0.25022052 | R13: =HYPERLINK("https://www.digrin.com/stocks/detail/VTV/price", "Verified Price & 10-K/Prospectus (VTV)")
A14: 12 | B14: SCHD | C14: Schwab U.S. Dividend Equity ETF | D14: ETF | E14: US Equity - Quality Dividend Growth | F14: NYSE Arca | G14: 2011 | H14: New ETF (+2) | I14: Y (96/96 + 36 OOS) | J14: Tier 2: Quality Cash-Flow & Spending-Rule Yield Sleeve | K14: TCO: Expense Ratio 0.06%, Tracking Difference -0.05%/yr; AUM $43.5B (12/2022); Bid-Ask Spread 0.01%; Dividend Yield ~3.4% (2022); Top-10 weight 40.8% (4% single-stock cap, 25% sector cap); Turnover 28%/yr; Sharpe Ratio 0.75 (highest of all 8 ETFs!). | L14: Tracks Dow Jones U.S. Dividend 100 Index: requires 10+ consecutive years of dividends, then ranks by 4 fundamental quality pillars (Cash Flow-to-Total Debt, ROE, Dividend Yield, 5-Yr Dividend Growth), excluding REITs; Annual March reconstitution. | M14: Directly bridges the Endowment's 4.5%-5.0% annual spending rule by generating ~3.4% organic cash dividend yield backed by high-ROIC, low-debt balance sheets (2015-2022 CAGR 11.78%/yr, MDD -21.50%, Downside Beta 0.84). | N14: 0.1177705 | O14: 0.15375342 | P14: 0.74810368 | Q14: -0.21499014 | R14: =HYPERLINK("https://www.digrin.com/stocks/detail/SCHD/price", "Verified Price & 10-K/Prospectus (SCHD)")
A15: 13 | B15: RSP | C15: Invesco S&P 500 Equal Weight ETF | D15: ETF | E15: US Equity - Equal-Weight De-Concentration | F15: NYSE Arca | G15: 2003 | H15: New ETF (+3) | I15: Y (96/96 + 36 OOS) | J15: Tier 1/3: Anti-Concentration & Mid-Cap Rebalancing Sleeve | K15: TCO: Expense Ratio 0.20%, Tracking Difference -0.22%/yr; AUM $32.8B (12/2022); Bid-Ask Spread 0.01%; Top-10 weight only 2.4% (0.20% per stock, HHI = 20 vs ~145 for cap-weighted S&P 500); Turnover 24%/yr; SMB +0.16, HML +0.23. | L15: Tracks S&P 500 Equal Weight Index: assigns 0.20% weight to each S&P 500 constituent and rebalances quarterly (Mar/Jun/Sep/Dec), mechanically trimming overvalued mega-cap winners and buying undervalued laggards ('contrarian rebalancing premium'). | M15: Eliminates the Institutional Crowding & Mega-Cap Concentration Risk embedded in VTI/SPY/QQQ (where Top-10 stocks exceed 25%-50% of NAV), providing broad participation across all 11 GICS sectors. | N15: 0.091990198 | O15: 0.17193332 | P15: 0.55038042 | Q15: -0.26675694 | R15: =HYPERLINK("https://www.digrin.com/stocks/detail/RSP/price", "Verified Price & 10-K/Prospectus (RSP)")
A16: 14 | B16: QQQ | C16: Invesco QQQ Trust | D16: ETF | E16: US Equity - Secular Innovation & Tech Growth | F16: NASDAQ | G16: 1999 | H16: New ETF (+4) | I16: Y (96/96 + 36 OOS) | J16: Tier 3: High-Conviction Secular Growth & Innovation Sleeve | K16: TCO: Expense Ratio 0.20%, Tracking Difference -0.19%/yr; AUM $148.5B (12/2022); #2 most liquid ETF globally ($12B+/day ADV, 0.01% spread); Top-10 weight 51.2% (AAPL, MSFT, AMZN, NVDA, GOOGL); FF3 R² = 93.71%, HML Beta -0.37. | L16: Tracks Nasdaq-100 Index (100 largest non-financial companies on Nasdaq); Unit Investment Trust (UIT) structure with Full Physical Replication; captures secular R&D compounders in Cloud, AI, Semiconductors, and Biotech. | M16: Delivers powerful long-term capital appreciation (13.49%/yr in 2015-2022; +32.92%/yr in 2023-2025) to beat HEPI inflation, while our FF3 test proves its alpha (+2.22%/yr, p=0.21) is pure Growth factor exposure requiring strict weight caps (<10-15%) to respect the 15% MDD limit. | N16: 0.13486004 | O16: 0.19082379 | P16: 0.71651748 | Q16: -0.32578054 | R16: =HYPERLINK("https://www.digrin.com/stocks/detail/QQQ/price", "Verified Price & 10-K/Prospectus (QQQ)")
A17: 15 | B17: VUG | C17: Vanguard Growth ETF | D17: ETF | E17: US Equity - Low-Cost Large Cap Growth | F17: NYSE Arca | G17: 2004 | H17: New ETF (+5) | I17: Y (96/96 + 36 OOS) | J17: Tier 3: Low-Cost Large-Cap Growth Factor Sleeve | K17: TCO: Expense Ratio 0.04% (5x cheaper than QQQ's 0.20%), Tracking Difference -0.03%/yr; AUM $70.6B (12/2022); Bid-Ask Spread 0.01%; Top-10 weight 46.5%; Turnover 8%/yr; FF3 R² = 97.23%, Beta_Mkt 1.08, Beta_HML -0.31. | L17: Tracks CRSP US Large Cap Growth Index (6-factor growth composite: 3-yr historic EPS/Sales growth, I/B/E/S forward EPS growth, Investment-to-Assets, ROA) across ~250 NYSE + Nasdaq stocks with CRSP migration bands. | M17: Institutional low-cost alternative to QQQ (4 bps vs 20 bps) that includes NYSE growth leaders (e.g., V, MA, LLY, HD) omitted by Nasdaq-only QQQ. | N17: 0.10459532 | O17: 0.18180398 | P17: 0.59300943 | Q17: -0.33154259 | R17: =HYPERLINK("https://www.digrin.com/stocks/detail/VUG/price", "Verified Price & 10-K/Prospectus (VUG)")
A18: 16 | B18: SPY | C18: SPDR S&P 500 ETF Trust | D18: ETF | E18: Broad US Large-Cap Benchmark | F18: NYSE Arca | G18: 1993 | H18: New ETF (+6) | I18: Y (96/96 + 36 OOS) | J18: Tier 1: Institutional Liquidity & Derivatives Benchmark | K18: TCO: Expense Ratio 0.0945%, Tracking Difference -0.09%/yr; AUM $358B (12/2022); #1 most liquid security in the world ($35B+/day ADV, sub-penny spread); Top-10 weight 25.4%; Turnover 2%/yr; FF3 R² = 99.59%, Alpha +0.15%/yr (p=0.68). | L18: Tracks S&P 500 Index (500 leading US large-caps with positive GAAP earnings filter); Unit Investment Trust (UIT) structure; deepest options/futures ecosystem globally for institutional tail-risk hedging. | M18: Included to reconcile the original workbook's split-brain tabs ('Stock Returns' used SPY while 'Returns_data' used VTI) and to provide large-cap S&P 500 benchmarking with GAAP profitability screening. | N18: 0.10065286 | O18: 0.15912674 | P18: 0.63096325 | Q18: -0.23927553 | R18: =HYPERLINK("https://www.digrin.com/stocks/detail/SPY/price", "Verified Price & 10-K/Prospectus (SPY)")
A19: 17 | B19: AAPL | C19: Apple Inc. | D19: Stock | E19: Information Technology | F19: NASDAQ | G19: 1980 | H19: New Stock (IT +1) | I19: Y (96/96 + 36 OOS) | J19: Tier 3: Ecosystem Compounder & Cash-Return Titan | K19: ROIC >45.0% vs WACC 8.2% (Spread +36.8%, negative cash conversion cycle); OCF/NI 1.19x ($122B OCF in FY2022); ADV >$11B/day; AA+ credit rating with $169B cash/marketable securities. | L19: Transition from hardware cycles to high-margin Services ecosystem (>78% gross margin on App Store, iCloud, Apple Pay; 900M+ paid subscriptions by 2022); history's largest share repurchase program ($550B+ bought back 2015-2022); 4-for-1 split Aug 2020. | M19: Provides 22.98%/yr CAGR and 0.83 Sharpe (2015-2022) with massive FCF yield, though high weight in VTI/QQQ/SPY requires look-through capping to avoid single-issuer concentration. | N19: 0.22976584 | O19: 0.29129633 | P19: 0.82951259 | Q19: -0.30461847 | R19: =HYPERLINK("https://www.digrin.com/stocks/detail/AAPL/price", "Verified Price & 10-K/Prospectus (AAPL)")
A20: 18 | B20: CSCO | C20: Cisco Systems, Inc. | D20: Stock | E20: Information Technology | F20: NASDAQ | G20: 1990 | H20: New Stock (IT +2) | I20: Y (96/96 + 36 OOS) | J20: Tier 2: High-Yield Legacy Tech & Enterprise Infrastructure | K20: ROIC 19.4% vs WACC 7.5% (Spread +11.9%); OCF/NI 1.28x (deferred revenue from software/security subscriptions); AA- balance sheet with net cash position through most of 2015-2022; ~3.1% dividend yield. | L20: Chuck Robbins' pivot from cyclical hardware switching/routing toward recurring software & cybersecurity (Duo Security 2018, ThousandEyes 2020, Splunk strategy); conservative capital return (>50% FCF to dividends + buybacks). | M20: Lowers overall IT sector valuation & duration risk (Downside Beta 0.60 vs NVDA's 1.78), providing steady dividend income within the Technology sleeve. | N20: 0.10357749 | O20: 0.24773342 | P20: 0.4868013 | Q20: -0.35496665 | R20: =HYPERLINK("https://www.digrin.com/stocks/detail/CSCO/price", "Verified Price & 10-K/Prospectus (CSCO)")
A21: 19 | B21: TXN | C21: Texas Instruments Inc. | D21: Stock | E21: Information Technology | F21: NASDAQ | G21: 1953 | H21: New Stock (IT +3) | I21: Y (96/96 + 36 OOS) | J21: Tier 2/3: Analog Semiconductor FCF-per-Share Compounder | K21: ROIC 34.6% vs WACC 8.1% (Spread +26.5%); FCF Margin 32%-36% of revenue; OCF/NI 1.15x; A+ credit rating; 19 consecutive years of dividend increases (24% CAGR 2004-2022) and -47% share count reduction. | L21: Gold-standard institutional capital allocation memo: CEO Rich Templeton explicitly manages TXN to maximize long-term FCF/share via 300mm wafer fab cost advantage (40% lower chip cost) and long-lifecycle industrial/automotive analog catalog. | M21: Delivers 18.21%/yr CAGR with a remarkably low Max Drawdown (-21.55% in 2015-2022, lowest among all IT stocks!) and positive HML value tilt (+0.14), acting as a quality industrial-tech bridge. | N21: 0.18214542 | O21: 0.22400513 | P21: 0.82386745 | Q21: -0.2154613 | R21: =HYPERLINK("https://www.digrin.com/stocks/detail/TXN/price", "Verified Price & 10-K/Prospectus (TXN)")
A22: 20 | B22: NVDA | C22: NVIDIA Corp. | D22: Stock | E22: Information Technology | F22: NASDAQ | G22: 1999 | H22: New Stock (IT +4) | I22: Y (96/96 + 36 OOS) | J22: Tier 3: High-Beta AI/GPU Secular Alpha Satellite | K22: ROIC averaged 29.8% (2015-2022); 2015-2022 CAGR 53.22%/yr, FF3 Alpha +35.52%/yr (p=0.0085); Caveat: Annualized Volatility 46.26%, Market Beta 1.71, Downside Beta 1.78, and Max Drawdown -62.82% (2021-2022 crypto/gaming inventory reset). | L22: Jensen Huang's 15-year CUDA software moat & Data Center architecture pivot (Pascal 2016, Volta 2017, Ampere 2020, Mellanox acquisition 2020) transformed GPUs into the monopoly compute engine for AI and HPC. | M22: Highest alpha generator in the entire 39-asset universe (+35.5%/yr FF3 Alpha in 2015-2022; +133.8%/yr OOS in 2023-2025), but its -62.8% drawdown and 1.78 Downside Beta mandate a strict <2%-3% satellite weight cap for an Endowment. | N22: 0.53219675 | O22: 0.46263417 | P22: 1.1481806 | Q22: -0.62818545 | R22: =HYPERLINK("https://www.digrin.com/stocks/detail/NVDA/price", "Verified Price & 10-K/Prospectus (NVDA)")
A23: 21 | B23: PFE | C23: Pfizer Inc. | D23: Stock | E23: Health Care | F23: NYSE | G23: 1942 | H23: New Stock (HC +1) | I23: Y (96/96 + 36 OOS) | J23: Tier 2: High-Yield Biopharma & Pandemic Counter-Cyclical | K23: ROIC jumped from 11.2% (2015-2019) to >26% (2021-2022 on Comirnaty/Paxlovid windfall, $100B FY2022 revenue); Market Beta 0.75, Downside Beta 0.48; ~3.8% dividend yield; Low R² (26.5%) offers strong idiosyncratic diversification. | L23: 2019-2020 strategic restructuring (spun off Upjohn generics into Viatris to become a pure-play biopharma); historic BioNTech mRNA partnership (2020-2022); Caveat: 2023-2025 post-COVID revenue cliff (-16.7%/yr OOS) highlights patent/product cycle risk. | M23: Reconciles the original workbook's 'Stock Returns' tab while illustrating why Endowment biopharma holdings must be diversified across therapeutic pipelines rather than reliant on single-product windfalls. | N23: 0.11085039 | O23: 0.23207853 | P23: 0.52998849 | Q23: -0.26028313 | R23: =HYPERLINK("https://www.digrin.com/stocks/detail/PFE/price", "Verified Price & 10-K/Prospectus (PFE)")
A24: 22 | B24: ABT | C24: Abbott Laboratories | D24: Stock | E24: Health Care | F24: NYSE | G24: 1929 | H24: New Stock (HC +2) | I24: Y (96/96 + 36 OOS) | J24: Tier 2/3: MedTech & Diagnostics Dividend Aristocrat | K24: ROIC 14.8% vs WACC 6.7% (Spread +8.1%); OCF/NI 1.32x; AA- credit rating, Interest Coverage 18.4x; 50+ consecutive years of dividend increases (Dividend King); 2015-2022 CAGR 13.92%/yr, Sharpe 0.69. | L24: Balanced 4-pillar model (Medical Devices led by FreeStyle Libre continuous glucose monitor; Diagnostics; Established Pharmaceuticals in emerging markets; Nutrition); successful integration of St. Jude Medical (2017). | M24: Provides steady med-tech growth (Downside Beta 0.57) that is insulated from binary FDA drug-trial failures and Medicare Part D drug-price negotiation risks. | N24: 0.13916848 | O24: 0.20647756 | P24: 0.69464389 | Q24: -0.30418162 | R24: =HYPERLINK("https://www.digrin.com/stocks/detail/ABT/price", "Verified Price & 10-K/Prospectus (ABT)")
A25: 23 | B25: MRK | C25: Merck & Co., Inc. | D25: Stock | E25: Health Care | F25: NYSE | G25: 1946 | H25: New Stock (HC +3) | I25: Y (96/96 + 36 OOS) | J25: Tier 2: Negative-Downside-Beta Oncology & Vaccine Anchor | K25: ROIC 21.6% vs WACC 6.3% (Spread +15.3%); OCF/NI 1.27x; A+ credit rating; Market Beta 0.48, Downside Beta -0.44 (rare negative downside beta!), 2015-2022 Max Drawdown only -17.62%, and surging +49% in the 2022 bear market. | L25: Immuno-oncology dominance via Keytruda ($20.9B sales in FY2022 across 30+ cancer indications) + Gardasil HPV vaccine monopoly; 2021 Organon spin-off shed off-patent legacy drugs; Caveat: Keytruda 2028 LOE concentration (>35% revenue). | M25: Acts as an exceptional crisis hedge inside the Equity sleeve: its negative Downside Beta (-0.44) and low correlation with Tech/Financials actively compress portfolio variance during market sell-offs. | N25: 0.12849259 | O25: 0.19704411 | P25: 0.67087308 | Q25: -0.17616287 | R25: =HYPERLINK("https://www.digrin.com/stocks/detail/MRK/price", "Verified Price & 10-K/Prospectus (MRK)")
A26: 24 | B26: LLY | C26: Eli Lilly and Co. | D26: Stock | E26: Health Care | F26: NYSE | G26: 1952 | H26: New Stock (HC +4) | I26: Y (96/96 + 36 OOS) | J26: Tier 3: High-Alpha Metabolic/Incretin & Immunology Leader | K26: ROIC 24.5% vs WACC 6.5% (Spread +18.0%); 2015-2022 CAGR 25.90%/yr, Sharpe 1.07, Market Beta 0.26, Downside Beta 0.10, Max Drawdown only -20.16%, and #2 highest statistically significant FF3 Alpha (+22.65%/yr, p=0.0056, R²=12.9%). | L26: Industry-leading R&D productivity in diabetes/obesity incretins (Trulicity 2015-2022, Mounjaro/tirzepatide FDA approval May 2022), immunology (Taltz), and oncology (Verzenio); spun off Elanco Animal Health (2018-2019). | M26: The single best risk-adjusted stock in the 39-asset universe across both 2015-2022 (25.9%/yr CAGR, Beta 0.26) and 2023-2025 OOS (+44.4%/yr CAGR), combining venture-like R&D alpha with bond-like low market correlation. | N26: 0.25895137 | O26: 0.23403664 | P26: 1.0700871 | Q26: -0.20156301 | R26: =HYPERLINK("https://www.digrin.com/stocks/detail/LLY/price", "Verified Price & 10-K/Prospectus (LLY)")
A27: 25 | B27: BAC | C27: Bank of America Corp. | D27: Stock | E27: Financials | F27: NYSE | G27: 1973 | H27: New Stock (FIN +1) | I27: Y (96/96 + 36 OOS) | J27: Tier 3: High-Beta Rate-Sensitive Retail Deposit Franchise | K27: ROTCE improved from 7.5% (2015) to 15.8% (2021-2022); Market Beta 1.38, HML Value Beta +0.97 (p<0.001); CET1 ratio 11.2%; Caveat: large Held-to-Maturity (HTM) agency MBS portfolio accumulated in 2020-2021 created unrealized duration losses in 2022. | L27: Brian Moynihan's 'Responsible Growth' strategy post-GFC slashed credit card charge-offs and built a $1.0T+ low-cost US consumer deposit base; Berkshire Hathaway (#1 shareholder) provided institutional governance validation. | M27: Reconciles the original workbook's 'Stock Returns' tab and provides high-beta cyclical value exposure (HML +0.97), though inferior to JPM in asset-liability duration management during 2022. | N27: 0.10082454 | O27: 0.30576015 | P27: 0.43978654 | Q27: -0.39336699 | R27: =HYPERLINK("https://www.digrin.com/stocks/detail/BAC/price", "Verified Price & 10-K/Prospectus (BAC)")
A28: 26 | B28: BLK | C28: BlackRock, Inc. | D28: Stock | E28: Financials | F28: NYSE | G28: 1999 | H28: New Stock (FIN +2) | I28: Y (96/96 + 36 OOS) | J28: Tier 3: Capital-Light Asset Management & FinTech Compounder | K28: ROIC 14.9% (over 30% tangible ROIC excluding goodwill), Operating Margin >40%, OCF/NI 1.15x; AA- credit rating (minimal balance-sheet credit risk compared to commercial banks); 2015-2022 CAGR 11.71%/yr, Market Beta 1.31. | L28: Global #1 asset manager (AUM grew from $4.6T in 2015 to $8.6T in 2022, peaking at $10T in 2021) driven by iShares ETF dominance and Aladdin enterprise risk-management software ($1.4B+ recurring tech revenue). | M28: Diversifies the Financials sleeve away from bank credit/loan-loss risk into capital-light fee-on-AUM and institutional SaaS revenue (Aladdin), directly aligned with the secular shift toward ETFs. | N28: 0.11709849 | O28: 0.25656097 | P28: 0.52792703 | Q28: -0.40151425 | R28: =HYPERLINK("https://www.digrin.com/stocks/detail/BLK/price", "Verified Price & 10-K/Prospectus (BLK)")
A29: 27 | B29: AXP | C29: American Express Co. | D29: Stock | E29: Financials | F29: NYSE | G29: 1977 | H29: New Stock (FIN +3) | I29: Y (96/96 + 36 OOS) | J29: Tier 3: Affluent Closed-Loop Payments & Inflation Toll-Road | K29: ROE >28.0% vs COE 9.8% (Spread +18.2%); HML Beta +0.59, Market Beta 1.10; Net Write-off Rate <2.0% (lowest in card industry due to prime/super-prime cardmember base); 2023-2025 OOS CAGR +37.49%/yr. | L29: Unique closed-loop network (issuer + acquirer + network) capturing merchant discount fees (2.3%-2.5% of transaction value) + annual Platinum/Gold card subscription fees; Berkshire Hathaway 20%+ permanent anchor stake. | M29: Acts as an automatic inflation hedge inside Financials: because merchant discount revenue is a percentage of nominal spending on travel, dining, and business T&E, nominal price inflation directly expands AXP's top-line fee pool. | N29: 0.075553865 | O29: 0.26202743 | P29: 0.37883374 | Q29: -0.41438356 | R29: =HYPERLINK("https://www.digrin.com/stocks/detail/AXP/price", "Verified Price & 10-K/Prospectus (AXP)")
A30: 28 | B30: KO | C30: The Coca-Cola Co. | D30: Stock | E30: Consumer Staples | F30: NYSE | G30: 1919 | H30: New Stock (CS +1) | I30: Y (96/96 + 36 OOS) | J30: Tier 2: Global Beverage Toll-Road & Low-Beta Income | K30: ROIC 18.5% vs WACC 6.0% (Spread +12.5%); Operating Margin >28% post-refranchising; OCF/NI 1.18x; A+ credit rating; 60 consecutive years of dividend increases (~3.0% yield); Market Beta 0.61, Downside Beta 0.47, SMB -0.75. | L30: 2015-2019 strategic refranchising of capital-intensive bottling territories transformed KO into a high-margin concentrate & brand owner (Costa Coffee 2019, Fairlife 2020, BodyArmor 2021); +11% price/mix pass-through in 2022. | M30: Reconciles the original workbook's 'Stock Returns' tab and provides dependable dividend cash flow and low market beta (0.61) to support annual Endowment spending distributions. | N30: 0.086898375 | O30: 0.16116143 | P30: 0.54753159 | Q30: -0.2356556 | R30: =HYPERLINK("https://www.digrin.com/stocks/detail/KO/price", "Verified Price & 10-K/Prospectus (KO)")
A31: 29 | B31: PEP | C31: PepsiCo, Inc. | D31: Stock | E31: Consumer Staples | F31: NASDAQ | G31: 1919 | H31: New Stock (CS +2) | I31: Y (96/96 + 36 OOS) | J31: Tier 2: Snack-Plus-Beverage Quality Defensive Leader | K31: ROIC 17.8% vs WACC 6.1% (Spread +11.7%); negative working capital; A+ credit rating; 50 consecutive years of dividend growth; 2015-2022 CAGR 11.61%/yr, Volatility 15.27% (lowest of all 31 stocks!), Sharpe 0.74, MDD only -15.47%, Downside Beta 0.32. | L31: Frito-Lay North America (>55% of operating profit, dominant salty-snack shelf space with zero private-label threat) + Pepsi beverages; demonstrated +14% organic price/mix power in 2022 under CEO Ramon Laguarta. | M31: Superior risk-adjusted staple over KO during 2015-2022 (Sharpe 0.74 vs 0.55, MDD -15.47% vs -23.57%) because Frito-Lay's at-home snacking boomed during 2020 lockdowns when KO's away-from-home fountain sales fell. | N31: 0.11608233 | O31: 0.15266881 | P31: 0.74206518 | Q31: -0.15472152 | R31: =HYPERLINK("https://www.digrin.com/stocks/detail/PEP/price", "Verified Price & 10-K/Prospectus (PEP)")
A32: 30 | B32: WMT | C32: Walmart Inc. | D32: Stock | E32: Consumer Staples | F32: NYSE | G32: 1972 | H32: New Stock (CS +3) | I32: Y (96/96 + 36 OOS) | J32: Tier 2: Counter-Cyclical Trade-Down Hedge & Negative Downside Beta | K32: ROIC 13.4% vs WACC 5.9% (Spread +7.5%); OCF $28.8B (FY2022); AA credit rating; Market Beta 0.53, FF3 R² = 23.3%, and rare negative Downside Beta (-0.35 vs VTI!) — WMT gained during the Feb-Mar 2020 COVID crash; 3-for-1 split in Feb 2024. | L32: Doug McMillon's omnichannel transformation (2016 Jet.com acquisition, 4,700+ US stores converted into curbside pickup/delivery nodes, Walmart+ membership, and high-margin Walmart Connect advertising); #1 US grocer (>25% market share). | M32: Provides a powerful consumer trade-down hedge: when inflation or recession squeezes households, middle- and high-income shoppers trade down to Walmart grocery, driving negative Downside Beta (-0.35) and +34.7%/yr OOS return in 2023-2025. | N32: 0.087946033 | O32: 0.19018207 | P32: 0.49529628 | Q32: -0.3207629 | R32: =HYPERLINK("https://www.digrin.com/stocks/detail/WMT/price", "Verified Price & 10-K/Prospectus (WMT)")
A33: 31 | B33: CVX | C33: Chevron Corp. | D33: Stock | E33: Energy | F33: NYSE | G33: 1921 | H33: New Stock (EN +1) | I33: Y (96/96 + 36 OOS) | J33: Tier 2/3: Fortress-Balance-Sheet Integrated Energy & Inflation Hedge | K33: 2015-2022 CAGR 10.74%/yr (outperforming XOM's 7.05%/yr by +369 bps/yr!) with lower Max Drawdown (-40.66% vs XOM's -57.71%); Net Debt-to-Capital <15% (AA- credit rating); 35 consecutive years of dividend increases; HML Beta +0.98. | L33: Walked away from the overpriced Anadarko bidding war in 2019 (collecting a $1B breakup fee) and bought Noble Energy at the 2020 cycle bottom; advantaged Permian Basin royalty acreage (zero royalty cost on legacy land grants) and Tengiz/Gorgon LNG. | M33: Higher-quality integrated energy alternative to XOM during 2015-2022: CVX protected its dividend and balance sheet through the 2020 negative-oil-price shock while delivering +58% total return in the 2022 inflation spike. | N33: 0.10740745 | O33: 0.28986973 | P33: 0.46291115 | Q33: -0.40660793 | R33: =HYPERLINK("https://www.digrin.com/stocks/detail/CVX/price", "Verified Price & 10-K/Prospectus (CVX)")
A34: 32 | B34: COP | C34: ConocoPhillips | D34: Stock | E34: Energy | F34: NYSE | G34: 1917 | H34: New Stock (EN +2) | I34: Y (96/96 + 36 OOS) | J34: Tier 3: Pure-Play Upstream E&P & Variable Cash-Return Leader | K34: ROIC surged to >27% in 2022; 2015-2022 CAGR 10.42%/yr, Volatility 39.77%, HML Beta +1.49; A- credit rating with <$28/bbl WTI breakeven cost of supply. | L34: Pioneered the E&P 'Return of Capital' framework (>30% of OCF returned via base dividend + Variable Return of Cash [VROC] + buybacks); Opportunistic low-cost Permian acquisitions (Concho Resources late 2020, Shell Permian 2021). | M34: Provides higher direct oil-beta torque than integrated refiners (XOM/CVX) for tactical inflation hedging, though its 39.8% volatility and -60.5% MDD require small position sizing. | N34: 0.10418715 | O34: 0.39772307 | P34: 0.4214707 | Q34: -0.60513509 | R34: =HYPERLINK("https://www.digrin.com/stocks/detail/COP/price", "Verified Price & 10-K/Prospectus (COP)")
A35: 33 | B35: SLB | C35: SLB (formerly Schlumberger) | D35: Stock | E35: Energy | F35: NYSE | G35: 1962 | H35: New Stock (EN +3) | I35: Y (96/96 + 36 OOS) | J35: Tier 3: Global Oilfield Services & Capex Cycle Diagnostic | K35: 2015-2022 CAGR -2.88%/yr, Volatility 43.65%, Max Drawdown -82.98%, Downside Beta 1.92, Market Beta 1.52, HML Beta +1.78; suffered $11B+ goodwill/asset impairments in 2019-2020 and a 75% dividend cut in April 2020. | L35: World's #1 offshore and international oilfield services & digital reservoir technology provider (>75% revenue outside North America); pivoted in 2020-2022 under CEO Olivier Le Peuch toward capital-light digital software and New Energy. | M35: Included as a critical empirical case study in 'Value Trap & Capex Cycle Risk': proves why an Endowment must not blindly buy high-HML energy stocks without screening for ROIC stability, asset writedowns, and -83% tail-drawdown risk. | N35: -0.028839719 | O35: 0.43652775 | P35: 0.13724525 | Q35: -0.82983988 | R35: =HYPERLINK("https://www.digrin.com/stocks/detail/SLB/price", "Verified Price & 10-K/Prospectus (SLB)")
A36: 34 | B36: MCD | C36: McDonald's Corp. | D36: Stock | E36: Consumer Discretionary | F36: NYSE | G36: 1965 | H36: New Stock (CD +1) | I36: Y (96/96 + 36 OOS) | J36: Tier 2/3: Franchise Real-Estate Toll-Road & Defensive Discretionary | K36: ROIC >22.0% vs WACC 6.4% (Spread +15.6%); Operating Margin >43% post-refranchising; 2015-2022 CAGR 16.79%/yr, Volatility 17.54%, Sharpe 0.93, Downside Beta 0.67, Max Drawdown -23.18%, FF3 Alpha +9.07%/yr (p=0.0653); 46-yr dividend growth streak. | L36: 2015-2019 refranchising to 93%+ franchised restaurants converted MCD into a commercial real-estate landlord & royalty collector (rent + 4%-5% of gross sales); 'Accelerating the Arches' (3Ds: Digital, Delivery, Drive-Thru) drove rapid 2020-2022 comps. | M36: Behaves like a high-growth Consumer Staple with inflation-linked rent/royalty cash flows and recession trade-down resilience, delivering the highest Sharpe Ratio (0.93) in the Consumer Discretionary sector. | N36: 0.16794949 | O36: 0.17542365 | P36: 0.92785261 | Q36: -0.23177196 | R36: =HYPERLINK("https://www.digrin.com/stocks/detail/MCD/price", "Verified Price & 10-K/Prospectus (MCD)")
A37: 35 | B37: NKE | C37: NIKE, Inc. | D37: Stock | E37: Consumer Discretionary | F37: NYSE | G37: 1980 | H37: New Stock (CD +2) | I37: Y (96/96 + 36 OOS) | J37: Tier 3: Global Athletic Brand & Direct-to-Consumer Growth | K37: ROIC 26.4% (2015-2021 average); AA- credit rating with strong net cash buffer; 2015-2022 CAGR 12.96%/yr, Market Beta 0.99; Caveat: 2022 inventory glut and China COVID lockdowns triggered a -50.42% Max Drawdown (and -16.9%/yr OOS in 2023-2025). | L37: 'Consumer Direct Acceleration' (2017-2022) expanded NIKE Direct & SNKRS app digital sales to >42% of revenue, lifting gross margins through 2021 before wholesale channel alienation and supply-chain bullwhip hit in 2022. | M37: Illustrates brand-moat pricing power during 2015-2021 alongside supply-chain inventory and geopolitical (Greater China >17% EBIT) concentration risks that require disciplined position limits. | N37: 0.12955463 | O37: 0.25476979 | P37: 0.57359905 | Q37: -0.50417827 | R37: =HYPERLINK("https://www.digrin.com/stocks/detail/NKE/price", "Verified Price & 10-K/Prospectus (NKE)")
A38: 36 | B38: SBUX | C38: Starbucks Corp. | D38: Stock | E38: Consumer Discretionary | F38: NASDAQ | G38: 1992 | H38: New Stock (CD +3) | I38: Y (96/96 + 36 OOS) | J38: Tier 3: Global Beverage Habit & Negative-Working-Capital Float | K38: ROIC >29.0% vs WACC 7.4%; OCF/NI 1.25x supported by ~$1.6B in stored-value Starbucks Card / Rewards app customer float (0% cost of capital); 2015-2022 CAGR 13.75%/yr, Sharpe 0.63; BBB+ credit rating after leveraged buybacks in 2018-2019. | L38: 35,000+ global stores by 2022; Digital Rewards loyalty program (>28M active US members driving 55% of US tendered sales) and cold-beverage customization drove ticket growth; Caveat: 2021-2022 US store unionization headlines & China zero-COVID volatility. | M38: Provides high-ROIC experiential consumer growth backed by interest-free customer預paid float, while serving as a governance case study on leveraged buybacks and labor-relations headline risk for University Endowments. | N38: 0.13751493 | O38: 0.23407869 | P38: 0.63342317 | Q38: -0.37714073 | R38: =HYPERLINK("https://www.digrin.com/stocks/detail/SBUX/price", "Verified Price & 10-K/Prospectus (SBUX)")
A39: 37 | B39: DUK | C39: Duke Energy Corp. | D39: Stock | E39: Utilities | F39: NYSE | G39: 1961 | H39: New Stock (UT +1) | I39: Y (96/96 + 36 OOS) | J39: Tier 2: Pure-Play Regulated Electric & Gas Utility Ballast | K39: Allowed Regulated ROE ~9.6%-10.1%; Market Beta 0.38 (lowest of all 31 stocks alongside LLY!), 2015-2022 Max Drawdown only -18.81%, Volatility 17.31%, Dividend Yield ~4.0%; Interest Coverage 3.4x on regulated rate-base debt. | L39: Serves 8.2M electric customers across high-inflow Southeast/Midwest states (NC, SC, FL, IN, OH, KY); exited merchant generation and commercial renewables (2022 strategic review) to become a 100% regulated rate-base utility. | M39: Provides ultra-low Market Beta (0.38) and ~4.0% bond-like cash yield to anchor the Defensive Sleeve, with constructive Southeast demographic growth supporting 6%-7% annual rate-base expansion. | N39: 0.070502474 | O39: 0.17306849 | P39: 0.43152875 | Q39: -0.18809126 | R39: =HYPERLINK("https://www.digrin.com/stocks/detail/DUK/price", "Verified Price & 10-K/Prospectus (DUK)")
A40: 38 | B40: AEP | C40: American Electric Power Co. | D40: Stock | E40: Utilities | F40: NASDAQ | G40: 1949 | H40: New Stock (UT +2) | I40: Y (96/96 + 36 OOS) | J40: Tier 2: High-Voltage Transmission Grid & Regulated Utility | K40: Allowed ROE ~9.9%; 2015-2022 CAGR 9.47%/yr, Volatility 18.56%, Market Beta 0.42, FF3 R² = 22.4%, Dividend Yield ~3.5%; 112+ years of uninterrupted dividend payments. | L40: Owns the largest electricity transmission system in the US (40,000+ circuit miles, including 765kV ultra-high-voltage lines across 11 states in PJM, ERCOT, SPP) regulated by FERC formula rates with automatic capex recovery. | M40: Captures the multi-decade grid-modernization and data-center electrification capex cycle via FERC-regulated transmission assets with low equity market correlation. | N40: 0.094677357 | O40: 0.18560501 | P40: 0.53613534 | Q40: -0.25149117 | R40: =HYPERLINK("https://www.digrin.com/stocks/detail/AEP/price", "Verified Price & 10-K/Prospectus (AEP)")
...

Sheet C2_8Pillar_&_4Pillar_Matrix
A1: INSTITUTIONAL ENDOWMENT DUE DILIGENCE – 8-PILLAR SINGLE-STOCK MATRIX (31 STOCKS) & 4-PILLAR ETF MATRIX (8 ETFs) [2015–2022]
A3: PART I: 4-PILLAR INSTITUTIONAL ETF DUE DILIGENCE MATRIX (8 ETFs: 2 ORIGINAL + 6 EXPANDED, STRICTLY ANCHORED IN 2015–2022)
A4: Ticker | B4: ETF Name & Category | C4: Endowment Sleeve Role | D4: Pillar 1 (Quant): Total Cost of Ownership (ER, Tracking Diff, Tracking Error) | E4: Pillar 1 (Qual): Securities Lending & Rebalance Cost Optimization | F4: Pillar 2 (Quant): Two-Tier Liquidity (Implied Liquidity, ADV, Bid-Ask Spread, Prem/Disc) | G4: Pillar 2 (Qual): AP / Market Maker Ecosystem & Creation/Redemption Resilience | H4: Pillar 3 (Quant): Index Concentration (Top-10 Weight, HHI, Annual Turnover) | I4: Pillar 3 (Qual): Index Methodology & Front-Running Mitigation Rules | J4: Pillar 4 (Quant): Structure, AUM (12/2022) & Tax Drag / Dividend Withholding | K4: Pillar 4 (Qual): Replication Method & University ESG Proxy Voting Alignment | L4: Verified Source Link
A5: VTI | B5: Vanguard Total Stock Market ETF (Original Benchmark) | C5: Tier 1: Policy Benchmark & Core Liquidity Reservoir | D5: Expense Ratio: 0.03%; Tracking Difference: -0.01%/yr; Tracking Error: 0.03%/yr; FF3 Alpha: -0.20%/yr (p=0.43, pure market beta R²=99.82%). | E5: Vanguard returns 100% of net securities lending revenue to the fund, offsetting 2 bps of the 3 bps fee; internal crossing across Vanguard's $1.2T pool minimizes rebalance slippage. | F5: Secondary ADV: $1.1B/day; Underlying Implied Liquidity: >$45B/day; Bid-Ask Spread: 0.01% (1 bp); Max 2020 COVID discount to NAV: -0.18% (resolved within 1 trading day). | G5: 35+ active institutional Authorized Participants (Citadel,Jane Street, Virtu, BofA, JPM); custom creation/redemption baskets absorb $500M+ endowment tickets with zero market impact. | H5: ~3,950 holdings; Top-10 weight: 22.8% (AAPL+MSFT+NVDA = 11.8%); Effective HHI: 115; Portfolio Turnover: 3.0%/yr (ultra-low). | I5: CRSP US Total Market Index uses 'packeting' (50% migration bands over 5-day transition windows) so hedge funds cannot front-run index additions/deletions. | J5: AUM: $262B ETF ($1.2T total fund as of 12/2022); zero closure risk; 0% US dividend withholding for tax-exempt US university endowment; zero capital gains distributions. | K5: Full Physical Replication for Large/Mid/Small-cap + optimized sampling for micro-cap; Vanguard Investment Stewardship votes on board independence and climate risk disclosure. | L5: =HYPERLINK("https://www.digrin.com/stocks/detail/VTI/price", "Verified ETF Data (VTI)")
A6: USMV | B6: iShares MSCI USA Min Vol Factor ETF (Original Defensive) | C6: Tier 2: Low-Volatility Drawdown Shield (-15% Board Trigger Defense) | D6: Expense Ratio: 0.15%; Tracking Difference: -0.13%/yr; Tracking Error: 0.08%/yr; 2015-2022 Vol: 12.84% (lowest of all 39 assets), Sharpe: 0.71, MDD: -19.06%. | E6: BlackRock rebates ~65-70% of securities lending revenue to the ETF; semi-annual May/Nov rebalance uses multi-dealer algorithmic auctions to compress trading costs. | F6: Secondary ADV: $420M/day; Implied Liquidity of underlying low-vol large caps: >$18B/day; Bid-Ask Spread: 0.02%; tight NAV tracking during Mar 2020 and Sep 2022. | G6: Backed by BlackRock iShares' global AP network (40+ APs); in-kind creation/redemption purges low-basis shares so rebalancing never triggers taxable capital gains. | H6: ~170 holdings; Top-10 weight: only 15.8% (AAPL+MSFT+NVDA = 3.2%); Effective HHI: 92 (broadly diversified); Turnover: 21%/yr (capped by index turnover constraint). | I6: MSCI USA Minimum Volatility Index optimizes the Barra factor covariance matrix subject to single-stock cap (1.5%) and GICS sector caps (+/-5% vs parent index) to prevent utility/staples overcrowding. | J6: AUM: $27.4B (12/2022); institutional scale; tax-efficient in-kind redemption; ~1.8% dividend yield supports annual spending liquidity. | K6: Full Physical Replication; BlackRock Investment Stewardship (BIS) offers institutional 'Voting Choice' allowing university endowments to vote proxies according to their own ESG charter! | L6: =HYPERLINK("https://totalrealreturns.com/n/USMV", "Verified ETF Data (USMV)")
A7: SCHD | B7: Schwab U.S. Dividend Equity ETF (Expanded ETF +1) | C7: Tier 2: Quality Cash-Flow & Spending-Rule Yield Engine | D7: Expense Ratio: 0.06%; Tracking Difference: -0.05%/yr; Tracking Error: 0.05%/yr; 2015-2022 CAGR: 11.78%/yr, Sharpe: 0.75 (highest among all 8 ETFs!), MDD: -21.50%. | E7: Charles Schwab Asset Management keeps lending conservative and executes annual March reconstitution across liquid NYSE/Nasdaq large-caps with minimal market impact. | F7: Secondary ADV: $380M/day; Underlying Implied Liquidity: >$14B/day; Bid-Ask Spread: 0.01% ($0.01 penny spread); minimal NAV premium/discount. | G7: Deep AP institutional support; tight creation unit arbitrage ensures Endowment cash inflows/withdrawals for annual spending rules execute at NAV. | H7: 100 holdings; Top-10 weight: 40.8% (0.0% overlap with AAPL/MSFT/NVDA!); Effective HHI: 290; Turnover: 28%/yr. | I7: Dow Jones U.S. Dividend 100 Index requires 10+ consecutive years of dividends, minimum $500M float, and ranks by a 4-factor Quality composite (FCF-to-Total Debt, ROE, Dividend Yield, 5-Yr Dividend Growth) with 4% single-stock and 25% sector caps. | J7: AUM: $43.5B (12/2022); ~3.4% organic cash dividend yield directly funds 70%+ of the Endowment's 4.75% annual spending rule without selling shares in down markets. | K7: Full Physical Replication; excludes REITs so all payouts qualify as qualified dividends; strong balance-sheet screen (FCF/Debt) naturally filters out distressed value traps. | L7: =HYPERLINK("https://www.digrin.com/stocks/detail/SCHD/price", "Verified ETF Data (SCHD)")
A8: VTV | B8: Vanguard Value ETF (Expanded ETF +2) | C8: Tier 2/3: Large-Cap Value & Duration/Inflation Defense | D8: Expense Ratio: 0.04%; Tracking Difference: -0.02%/yr; Tracking Error: 0.04%/yr; HML Value Beta: +0.33 (p<0.001); lost only -2.1% in the 2022 inflation bear market. | E8: 100% of Vanguard securities lending income returned to fund; low 8%/yr turnover keeps implicit transaction drag near zero. | F8: Secondary ADV: $510M/day; Underlying Implied Liquidity: >$28B/day; Bid-Ask Spread: 0.01%; rock-solid NAV tracking during 2020 and 2022 rate shocks. | G8: Tier-1 Vanguard AP network; dual share-class structure (shared with Vanguard Value Index Admiral mutual fund) provides massive internal liquidity netting. | H8: ~340 holdings; Top-10 weight: 21.4% (BRK.B, UNH, JNJ, XOM, JPM, PG — 0% in AAPL/MSFT/NVDA); Effective HHI: 110; Turnover: 8%/yr. | I8: CRSP US Large Cap Value Index uses a 5-factor value composite (B/P, Forward E/P, Historic E/P, D/P, S/P) and CRSP packeting bands to eliminate index-rebalance front-running. | J8: AUM: $99.8B (12/2022); ~2.6% dividend yield; zero capital gains distributions since inception. | K8: Full Physical Replication; provides essential low-duration equity ballast when rising interest rates compress high-P/E growth multiples. | L8: =HYPERLINK("https://www.digrin.com/stocks/detail/VTV/price", "Verified ETF Data (VTV)")
A9: RSP | B9: Invesco S&P 500 Equal Weight ETF (Expanded ETF +3) | C9: Tier 1/3: Anti-Concentration & Contrarian Rebalancing Sleeve | D9: Expense Ratio: 0.20%; Tracking Difference: -0.22%/yr; Tracking Error: 0.06%/yr; captures SMB (+0.16) and HML (+0.23) premia with R² = 97.16%. | E9: Invesco securities lending program offsets ~2 bps; quarterly rebalancing systematically harvests the institutional 'rebalancing premium' (selling winners, buying laggards). | F9: Secondary ADV: $620M/day; Underlying Implied Liquidity: >$22B/day (all S&P 500 constituents); Bid-Ask Spread: 0.01%. | G9: 30+ active APs; in-kind quarterly rebalance swaps avoid realizing taxable capital gains inside the ETF wrapper. | H9: 500 holdings; Top-10 weight: ONLY 2.4% (0.20% per stock; AAPL+MSFT+NVDA = 0.6% vs 28.6% in QQQ!); Effective HHI: 20 (lowest concentration of all ETFs); Turnover: 24%/yr. | I9: S&P 500 Equal Weight Index resets every constituent to 0.20% on the 3rd Friday of Mar/Jun/Sep/Dec; S&P liquidity screens ensure even the smallest S&P 500 member has >$250M/day volume. | J9: AUM: $32.8B (12/2022); eliminates single-stock crowding risk if Mega-Cap Tech suffers antitrust or valuation mean-reversion. | K9: Full Physical Replication; Invesco proxy voting follows institutional governance guidelines. | L9: =HYPERLINK("https://www.digrin.com/stocks/detail/RSP/price", "Verified ETF Data (RSP)")
A10: QQQ | B10: Invesco QQQ Trust (Expanded ETF +4) | C10: Tier 3: Secular Innovation, R&D & AI Growth Engine | D10: Expense Ratio: 0.20%; Tracking Difference: -0.19%/yr; Tracking Error: 0.05%/yr; 2015-2022 CAGR: 13.49%/yr (OOS 2023-2025: +32.92%/yr), Sharpe: 0.72, MDD: -32.58%. | E10: Structured as a 1940-Act Unit Investment Trust (UIT), so QQQ cannot lend securities or reinvest dividends intra-quarter (causes ~1-2 bps cash drag in rising markets). | F10: Secondary ADV: >$12.0B/day (#2 most traded ETF globally); Bid-Ask Spread: <0.01% ($0.01); deepest options market alongside SPY for tail-risk collar hedging. | G10: 45+ global APs and market makers; instantaneous arbitrage keeps intraday premium/discount within +/-2 bps even during FOMC announcements. | H10: 100 holdings; Top-10 weight: 51.2% (AAPL+MSFT+NVDA = 28.6%, severe mega-cap concentration); Effective HHI: 410; Turnover: 7%/yr. | I10: Nasdaq-100 Index (modified market-cap weighted, excluding financials); special rebalance triggered if stocks >4.5% exceed 48% aggregate weight (executed in July 2023). | J10: AUM: $148.5B (12/2022); low 0.6%-0.8% dividend yield (pure capital appreciation focus). | K10: Full Physical Replication; FF3 regression proves QQQ's CAPM alpha (+3.69%/yr) shrinks to +2.22%/yr (p=0.209, indistinguishable from zero) once HML (-0.37) is controlled for—so QQQ must be sized as a capped Growth Factor sleeve. | L10: =HYPERLINK("https://www.digrin.com/stocks/detail/QQQ/price", "Verified ETF Data (QQQ)")
